2025-03-17 13:08:51,310 INFO    MainThread:1551413 [wandb_init.py:setup_run_log_directory():647] Logging user logs to /mnt/e_disk/DA6401-Assignment-1-DA24S008/wandb/run-20250317_130851-cswvapi7/logs/debug.log
2025-03-17 13:08:51,310 INFO    MainThread:1551413 [wandb_init.py:setup_run_log_directory():648] Logging internal logs to /mnt/e_disk/DA6401-Assignment-1-DA24S008/wandb/run-20250317_130851-cswvapi7/logs/debug-internal.log
2025-03-17 13:08:51,310 INFO    MainThread:1551413 [wandb_init.py:init():761] calling init triggers
2025-03-17 13:08:51,310 INFO    MainThread:1551413 [wandb_init.py:init():766] wandb.init called with sweep_config: {'activation': 'relu', 'batch_size': 64, 'epochs': 10, 'lr': 0.001, 'n_hidden': 5, 'n_hidden_units': 32, 'optim_algo': 'nesterov', 'weight_decay': 0.5, 'weight_init': 'xavier'}
config: {'_wandb': {}}
2025-03-17 13:08:51,310 INFO    MainThread:1551413 [wandb_init.py:init():776] wandb.init() called while a run is active
2025-03-17 13:09:16,116 INFO    MainThread:1551413 [jupyter.py:save_ipynb():386] not saving jupyter notebook
2025-03-17 13:09:16,116 INFO    MainThread:1551413 [wandb_init.py:_pause_backend():564] pausing backend
2025-03-17 13:13:01,665 INFO    MainThread:1551413 [wandb_init.py:_resume_backend():569] resuming backend
2025-03-17 13:13:01,669 INFO    MainThread:1551413 [jupyter.py:save_ipynb():386] not saving jupyter notebook
2025-03-17 13:13:01,669 INFO    MainThread:1551413 [wandb_init.py:_pause_backend():564] pausing backend
2025-03-17 13:13:09,984 INFO    MainThread:1551413 [wandb_init.py:_resume_backend():569] resuming backend
2025-03-17 13:13:09,988 INFO    MainThread:1551413 [jupyter.py:save_ipynb():386] not saving jupyter notebook
2025-03-17 13:13:09,988 INFO    MainThread:1551413 [wandb_init.py:_pause_backend():564] pausing backend
2025-03-17 13:13:13,118 INFO    MainThread:1551413 [wandb_init.py:_resume_backend():569] resuming backend
2025-03-17 13:14:02,909 INFO    MainThread:1551413 [wandb_init.py:setup_run_log_directory():647] Logging user logs to /mnt/e_disk/DA6401-Assignment-1-DA24S008/wandb/run-20250317_131402-cswvapi7/logs/debug.log
2025-03-17 13:14:02,909 INFO    MainThread:1551413 [wandb_init.py:setup_run_log_directory():648] Logging internal logs to /mnt/e_disk/DA6401-Assignment-1-DA24S008/wandb/run-20250317_131402-cswvapi7/logs/debug-internal.log
2025-03-17 13:14:02,909 INFO    MainThread:1551413 [wandb_init.py:init():761] calling init triggers
2025-03-17 13:14:02,909 INFO    MainThread:1551413 [wandb_init.py:init():766] wandb.init called with sweep_config: {'activation': 'relu', 'batch_size': 64, 'epochs': 10, 'lr': 0.001, 'n_hidden': 5, 'n_hidden_units': 32, 'optim_algo': 'nesterov', 'weight_decay': 0.5, 'weight_init': 'xavier'}
config: {'_wandb': {}}
2025-03-17 13:14:02,909 INFO    MainThread:1551413 [wandb_init.py:init():776] wandb.init() called while a run is active
2025-03-17 13:14:28,406 INFO    MainThread:1551413 [jupyter.py:save_ipynb():386] not saving jupyter notebook
2025-03-17 13:14:28,407 INFO    MainThread:1551413 [wandb_init.py:_pause_backend():564] pausing backend
2025-03-17 13:17:16,639 INFO    MainThread:1551413 [wandb_init.py:_resume_backend():569] resuming backend
2025-03-17 13:17:16,642 INFO    MainThread:1551413 [jupyter.py:save_ipynb():386] not saving jupyter notebook
2025-03-17 13:17:16,643 INFO    MainThread:1551413 [wandb_init.py:_pause_backend():564] pausing backend
2025-03-17 13:17:16,657 INFO    MainThread:1551413 [wandb_init.py:_resume_backend():569] resuming backend
2025-03-17 13:17:16,660 INFO    MainThread:1551413 [jupyter.py:save_ipynb():386] not saving jupyter notebook
2025-03-17 13:17:16,660 INFO    MainThread:1551413 [wandb_init.py:_pause_backend():564] pausing backend
2025-03-17 13:23:02,302 INFO    MainThread:1551413 [wandb_init.py:_resume_backend():569] resuming backend
2025-03-17 13:23:51,378 INFO    MainThread:1551413 [wandb_init.py:setup_run_log_directory():647] Logging user logs to /mnt/e_disk/DA6401-Assignment-1-DA24S008/wandb/run-20250317_132351-cswvapi7/logs/debug.log
2025-03-17 13:23:51,378 INFO    MainThread:1551413 [wandb_init.py:setup_run_log_directory():648] Logging internal logs to /mnt/e_disk/DA6401-Assignment-1-DA24S008/wandb/run-20250317_132351-cswvapi7/logs/debug-internal.log
2025-03-17 13:23:51,379 INFO    MainThread:1551413 [wandb_init.py:init():761] calling init triggers
2025-03-17 13:23:51,379 INFO    MainThread:1551413 [wandb_init.py:init():766] wandb.init called with sweep_config: {'activation': 'relu', 'batch_size': 64, 'epochs': 10, 'lr': 0.001, 'n_hidden': 5, 'n_hidden_units': 32, 'optim_algo': 'nesterov', 'weight_decay': 0.5, 'weight_init': 'xavier'}
config: {'_wandb': {}}
2025-03-17 13:23:51,379 INFO    MainThread:1551413 [wandb_init.py:init():776] wandb.init() called while a run is active
2025-03-17 13:23:51,516 INFO    MainThread:1551413 [jupyter.py:save_ipynb():386] not saving jupyter notebook
2025-03-17 13:23:51,516 INFO    MainThread:1551413 [wandb_init.py:_pause_backend():564] pausing backend
2025-03-17 13:23:51,521 INFO    MainThread:1551413 [wandb_init.py:_resume_backend():569] resuming backend
2025-03-17 13:23:51,524 INFO    MainThread:1551413 [jupyter.py:save_ipynb():386] not saving jupyter notebook
2025-03-17 13:23:51,526 INFO    MainThread:1551413 [wandb_init.py:_pause_backend():564] pausing backend
2025-03-17 13:24:59,818 INFO    MainThread:1551413 [wandb_init.py:_resume_backend():569] resuming backend
2025-03-17 13:25:06,012 WARNING MsgRouterThr:1551413 [router.py:message_loop():63] message_loop has been closed
Traceback (most recent call last):
  File "/mnt/e_disk/da24s008/lib/python3.10/site-packages/wandb/sdk/interface/router_sock.py", line 27, in _read_message
    return self._sock_client.read_server_response(timeout=1)
  File "/mnt/e_disk/da24s008/lib/python3.10/site-packages/wandb/sdk/lib/sock_client.py", line 235, in read_server_response
    data = self._read_packet_bytes(timeout=timeout)
  File "/mnt/e_disk/da24s008/lib/python3.10/site-packages/wandb/sdk/lib/sock_client.py", line 220, in _read_packet_bytes
    raise SockClientClosedError
wandb.sdk.lib.sock_client.SockClientClosedError

The above exception was the direct cause of the following exception:

Traceback (most recent call last):
  File "/mnt/e_disk/da24s008/lib/python3.10/site-packages/wandb/sdk/interface/router.py", line 56, in message_loop
    msg = self._read_message()
  File "/mnt/e_disk/da24s008/lib/python3.10/site-packages/wandb/sdk/interface/router_sock.py", line 29, in _read_message
    raise MessageRouterClosedError from e
wandb.sdk.interface.router.MessageRouterClosedError
2025-03-17 13:25:06,014 INFO    MsgRouterThr:1551413 [mailbox.py:close():129] Closing mailbox, abandoning 2 handles.
2025-03-17 13:25:06,618 INFO    MainThread:1551413 [jupyter.py:save_ipynb():386] not saving jupyter notebook
2025-03-17 13:25:06,618 INFO    MainThread:1551413 [wandb_init.py:_pause_backend():564] pausing backend
2025-03-17 13:25:11,046 INFO    MainThread:1551413 [wandb_init.py:_resume_backend():569] resuming backend
2025-03-17 13:25:11,047 ERROR   MainThread:1551413 [redirect.py:_on_write():661] error in stdout callback
Traceback (most recent call last):
  File "/mnt/e_disk/da24s008/lib/python3.10/site-packages/IPython/core/events.py", line 82, in trigger
    func(*args, **kwargs)
  File "/mnt/e_disk/da24s008/lib/python3.10/site-packages/wandb/sdk/wandb_init.py", line 570, in _resume_backend
    self.backend.interface.publish_resume()
  File "/mnt/e_disk/da24s008/lib/python3.10/site-packages/wandb/sdk/interface/interface.py", line 777, in publish_resume
    self._publish_resume(resume)
  File "/mnt/e_disk/da24s008/lib/python3.10/site-packages/wandb/sdk/interface/interface_shared.py", line 293, in _publish_resume
    self._publish(rec)
  File "/mnt/e_disk/da24s008/lib/python3.10/site-packages/wandb/sdk/interface/interface_sock.py", line 39, in _publish
    self._sock_client.send_record_publish(record)
  File "/mnt/e_disk/da24s008/lib/python3.10/site-packages/wandb/sdk/lib/sock_client.py", line 174, in send_record_publish
    self.send_server_request(server_req)
  File "/mnt/e_disk/da24s008/lib/python3.10/site-packages/wandb/sdk/lib/sock_client.py", line 154, in send_server_request
    self._send_message(msg)
  File "/mnt/e_disk/da24s008/lib/python3.10/site-packages/wandb/sdk/lib/sock_client.py", line 151, in _send_message
    self._sendall_with_error_handle(header + data)
  File "/mnt/e_disk/da24s008/lib/python3.10/site-packages/wandb/sdk/lib/sock_client.py", line 130, in _sendall_with_error_handle
    sent = self._sock.send(data)
BrokenPipeError: [Errno 32] Broken pipe

During handling of the above exception, another exception occurred:

Traceback (most recent call last):
  File "/mnt/e_disk/da24s008/lib/python3.10/site-packages/wandb/sdk/lib/redirect.py", line 659, in _on_write
    cb(written_data)
  File "/mnt/e_disk/da24s008/lib/python3.10/site-packages/wandb/sdk/wandb_run.py", line 2296, in <lambda>
    lambda data: self._console_raw_callback("stdout", data),
  File "/mnt/e_disk/da24s008/lib/python3.10/site-packages/wandb/sdk/wandb_run.py", line 401, in wrapper_fn
    return func(self, *args, **kwargs)
  File "/mnt/e_disk/da24s008/lib/python3.10/site-packages/wandb/sdk/wandb_run.py", line 1444, in _console_raw_callback
    self._backend.interface.publish_output_raw(name, data)
  File "/mnt/e_disk/da24s008/lib/python3.10/site-packages/wandb/sdk/interface/interface.py", line 761, in publish_output_raw
    self._publish_output_raw(o)
  File "/mnt/e_disk/da24s008/lib/python3.10/site-packages/wandb/sdk/interface/interface_shared.py", line 38, in _publish_output_raw
    self._publish(rec)
  File "/mnt/e_disk/da24s008/lib/python3.10/site-packages/wandb/sdk/interface/interface_sock.py", line 39, in _publish
    self._sock_client.send_record_publish(record)
  File "/mnt/e_disk/da24s008/lib/python3.10/site-packages/wandb/sdk/lib/sock_client.py", line 174, in send_record_publish
    self.send_server_request(server_req)
  File "/mnt/e_disk/da24s008/lib/python3.10/site-packages/wandb/sdk/lib/sock_client.py", line 154, in send_server_request
    self._send_message(msg)
  File "/mnt/e_disk/da24s008/lib/python3.10/site-packages/wandb/sdk/lib/sock_client.py", line 151, in _send_message
    self._sendall_with_error_handle(header + data)
  File "/mnt/e_disk/da24s008/lib/python3.10/site-packages/wandb/sdk/lib/sock_client.py", line 130, in _sendall_with_error_handle
    sent = self._sock.send(data)
BrokenPipeError: [Errno 32] Broken pipe
2025-03-17 13:25:11,049 ERROR   MainThread:1551413 [redirect.py:_on_write():661] error in stdout callback
Traceback (most recent call last):
  File "/mnt/e_disk/da24s008/lib/python3.10/site-packages/IPython/core/events.py", line 82, in trigger
    func(*args, **kwargs)
  File "/mnt/e_disk/da24s008/lib/python3.10/site-packages/wandb/sdk/wandb_init.py", line 570, in _resume_backend
    self.backend.interface.publish_resume()
  File "/mnt/e_disk/da24s008/lib/python3.10/site-packages/wandb/sdk/interface/interface.py", line 777, in publish_resume
    self._publish_resume(resume)
  File "/mnt/e_disk/da24s008/lib/python3.10/site-packages/wandb/sdk/interface/interface_shared.py", line 293, in _publish_resume
    self._publish(rec)
  File "/mnt/e_disk/da24s008/lib/python3.10/site-packages/wandb/sdk/interface/interface_sock.py", line 39, in _publish
    self._sock_client.send_record_publish(record)
  File "/mnt/e_disk/da24s008/lib/python3.10/site-packages/wandb/sdk/lib/sock_client.py", line 174, in send_record_publish
    self.send_server_request(server_req)
  File "/mnt/e_disk/da24s008/lib/python3.10/site-packages/wandb/sdk/lib/sock_client.py", line 154, in send_server_request
    self._send_message(msg)
  File "/mnt/e_disk/da24s008/lib/python3.10/site-packages/wandb/sdk/lib/sock_client.py", line 151, in _send_message
    self._sendall_with_error_handle(header + data)
  File "/mnt/e_disk/da24s008/lib/python3.10/site-packages/wandb/sdk/lib/sock_client.py", line 130, in _sendall_with_error_handle
    sent = self._sock.send(data)
BrokenPipeError: [Errno 32] Broken pipe

During handling of the above exception, another exception occurred:

Traceback (most recent call last):
  File "/mnt/e_disk/da24s008/lib/python3.10/site-packages/wandb/sdk/lib/redirect.py", line 659, in _on_write
    cb(written_data)
  File "/mnt/e_disk/da24s008/lib/python3.10/site-packages/wandb/sdk/wandb_run.py", line 2296, in <lambda>
    lambda data: self._console_raw_callback("stdout", data),
  File "/mnt/e_disk/da24s008/lib/python3.10/site-packages/wandb/sdk/wandb_run.py", line 401, in wrapper_fn
    return func(self, *args, **kwargs)
  File "/mnt/e_disk/da24s008/lib/python3.10/site-packages/wandb/sdk/wandb_run.py", line 1444, in _console_raw_callback
    self._backend.interface.publish_output_raw(name, data)
  File "/mnt/e_disk/da24s008/lib/python3.10/site-packages/wandb/sdk/interface/interface.py", line 761, in publish_output_raw
    self._publish_output_raw(o)
  File "/mnt/e_disk/da24s008/lib/python3.10/site-packages/wandb/sdk/interface/interface_shared.py", line 38, in _publish_output_raw
    self._publish(rec)
  File "/mnt/e_disk/da24s008/lib/python3.10/site-packages/wandb/sdk/interface/interface_sock.py", line 39, in _publish
    self._sock_client.send_record_publish(record)
  File "/mnt/e_disk/da24s008/lib/python3.10/site-packages/wandb/sdk/lib/sock_client.py", line 174, in send_record_publish
    self.send_server_request(server_req)
  File "/mnt/e_disk/da24s008/lib/python3.10/site-packages/wandb/sdk/lib/sock_client.py", line 154, in send_server_request
    self._send_message(msg)
  File "/mnt/e_disk/da24s008/lib/python3.10/site-packages/wandb/sdk/lib/sock_client.py", line 151, in _send_message
    self._sendall_with_error_handle(header + data)
  File "/mnt/e_disk/da24s008/lib/python3.10/site-packages/wandb/sdk/lib/sock_client.py", line 130, in _sendall_with_error_handle
    sent = self._sock.send(data)
BrokenPipeError: [Errno 32] Broken pipe
2025-03-17 13:25:14,497 INFO    MainThread:1551413 [jupyter.py:save_ipynb():386] not saving jupyter notebook
2025-03-17 13:25:14,497 INFO    MainThread:1551413 [wandb_init.py:_pause_backend():564] pausing backend
2025-03-17 13:25:14,498 ERROR   MainThread:1551413 [redirect.py:_on_write():661] error in stdout callback
Traceback (most recent call last):
  File "/mnt/e_disk/da24s008/lib/python3.10/site-packages/IPython/core/events.py", line 82, in trigger
    func(*args, **kwargs)
  File "/mnt/e_disk/da24s008/lib/python3.10/site-packages/wandb/sdk/wandb_init.py", line 565, in _pause_backend
    self.backend.interface.publish_pause()
  File "/mnt/e_disk/da24s008/lib/python3.10/site-packages/wandb/sdk/interface/interface.py", line 769, in publish_pause
    self._publish_pause(pause)
  File "/mnt/e_disk/da24s008/lib/python3.10/site-packages/wandb/sdk/interface/interface_shared.py", line 289, in _publish_pause
    self._publish(rec)
  File "/mnt/e_disk/da24s008/lib/python3.10/site-packages/wandb/sdk/interface/interface_sock.py", line 39, in _publish
    self._sock_client.send_record_publish(record)
  File "/mnt/e_disk/da24s008/lib/python3.10/site-packages/wandb/sdk/lib/sock_client.py", line 174, in send_record_publish
    self.send_server_request(server_req)
  File "/mnt/e_disk/da24s008/lib/python3.10/site-packages/wandb/sdk/lib/sock_client.py", line 154, in send_server_request
    self._send_message(msg)
  File "/mnt/e_disk/da24s008/lib/python3.10/site-packages/wandb/sdk/lib/sock_client.py", line 151, in _send_message
    self._sendall_with_error_handle(header + data)
  File "/mnt/e_disk/da24s008/lib/python3.10/site-packages/wandb/sdk/lib/sock_client.py", line 130, in _sendall_with_error_handle
    sent = self._sock.send(data)
BrokenPipeError: [Errno 32] Broken pipe

During handling of the above exception, another exception occurred:

Traceback (most recent call last):
  File "/mnt/e_disk/da24s008/lib/python3.10/site-packages/wandb/sdk/lib/redirect.py", line 659, in _on_write
    cb(written_data)
  File "/mnt/e_disk/da24s008/lib/python3.10/site-packages/wandb/sdk/wandb_run.py", line 2296, in <lambda>
    lambda data: self._console_raw_callback("stdout", data),
  File "/mnt/e_disk/da24s008/lib/python3.10/site-packages/wandb/sdk/wandb_run.py", line 401, in wrapper_fn
    return func(self, *args, **kwargs)
  File "/mnt/e_disk/da24s008/lib/python3.10/site-packages/wandb/sdk/wandb_run.py", line 1444, in _console_raw_callback
    self._backend.interface.publish_output_raw(name, data)
  File "/mnt/e_disk/da24s008/lib/python3.10/site-packages/wandb/sdk/interface/interface.py", line 761, in publish_output_raw
    self._publish_output_raw(o)
  File "/mnt/e_disk/da24s008/lib/python3.10/site-packages/wandb/sdk/interface/interface_shared.py", line 38, in _publish_output_raw
    self._publish(rec)
  File "/mnt/e_disk/da24s008/lib/python3.10/site-packages/wandb/sdk/interface/interface_sock.py", line 39, in _publish
    self._sock_client.send_record_publish(record)
  File "/mnt/e_disk/da24s008/lib/python3.10/site-packages/wandb/sdk/lib/sock_client.py", line 174, in send_record_publish
    self.send_server_request(server_req)
  File "/mnt/e_disk/da24s008/lib/python3.10/site-packages/wandb/sdk/lib/sock_client.py", line 154, in send_server_request
    self._send_message(msg)
  File "/mnt/e_disk/da24s008/lib/python3.10/site-packages/wandb/sdk/lib/sock_client.py", line 151, in _send_message
    self._sendall_with_error_handle(header + data)
  File "/mnt/e_disk/da24s008/lib/python3.10/site-packages/wandb/sdk/lib/sock_client.py", line 130, in _sendall_with_error_handle
    sent = self._sock.send(data)
BrokenPipeError: [Errno 32] Broken pipe
2025-03-17 13:25:14,498 ERROR   MainThread:1551413 [redirect.py:_on_write():661] error in stdout callback
Traceback (most recent call last):
  File "/mnt/e_disk/da24s008/lib/python3.10/site-packages/IPython/core/events.py", line 82, in trigger
    func(*args, **kwargs)
  File "/mnt/e_disk/da24s008/lib/python3.10/site-packages/wandb/sdk/wandb_init.py", line 565, in _pause_backend
    self.backend.interface.publish_pause()
  File "/mnt/e_disk/da24s008/lib/python3.10/site-packages/wandb/sdk/interface/interface.py", line 769, in publish_pause
    self._publish_pause(pause)
  File "/mnt/e_disk/da24s008/lib/python3.10/site-packages/wandb/sdk/interface/interface_shared.py", line 289, in _publish_pause
    self._publish(rec)
  File "/mnt/e_disk/da24s008/lib/python3.10/site-packages/wandb/sdk/interface/interface_sock.py", line 39, in _publish
    self._sock_client.send_record_publish(record)
  File "/mnt/e_disk/da24s008/lib/python3.10/site-packages/wandb/sdk/lib/sock_client.py", line 174, in send_record_publish
    self.send_server_request(server_req)
  File "/mnt/e_disk/da24s008/lib/python3.10/site-packages/wandb/sdk/lib/sock_client.py", line 154, in send_server_request
    self._send_message(msg)
  File "/mnt/e_disk/da24s008/lib/python3.10/site-packages/wandb/sdk/lib/sock_client.py", line 151, in _send_message
    self._sendall_with_error_handle(header + data)
  File "/mnt/e_disk/da24s008/lib/python3.10/site-packages/wandb/sdk/lib/sock_client.py", line 130, in _sendall_with_error_handle
    sent = self._sock.send(data)
BrokenPipeError: [Errno 32] Broken pipe

During handling of the above exception, another exception occurred:

Traceback (most recent call last):
  File "/mnt/e_disk/da24s008/lib/python3.10/site-packages/wandb/sdk/lib/redirect.py", line 659, in _on_write
    cb(written_data)
  File "/mnt/e_disk/da24s008/lib/python3.10/site-packages/wandb/sdk/wandb_run.py", line 2296, in <lambda>
    lambda data: self._console_raw_callback("stdout", data),
  File "/mnt/e_disk/da24s008/lib/python3.10/site-packages/wandb/sdk/wandb_run.py", line 401, in wrapper_fn
    return func(self, *args, **kwargs)
  File "/mnt/e_disk/da24s008/lib/python3.10/site-packages/wandb/sdk/wandb_run.py", line 1444, in _console_raw_callback
    self._backend.interface.publish_output_raw(name, data)
  File "/mnt/e_disk/da24s008/lib/python3.10/site-packages/wandb/sdk/interface/interface.py", line 761, in publish_output_raw
    self._publish_output_raw(o)
  File "/mnt/e_disk/da24s008/lib/python3.10/site-packages/wandb/sdk/interface/interface_shared.py", line 38, in _publish_output_raw
    self._publish(rec)
  File "/mnt/e_disk/da24s008/lib/python3.10/site-packages/wandb/sdk/interface/interface_sock.py", line 39, in _publish
    self._sock_client.send_record_publish(record)
  File "/mnt/e_disk/da24s008/lib/python3.10/site-packages/wandb/sdk/lib/sock_client.py", line 174, in send_record_publish
    self.send_server_request(server_req)
  File "/mnt/e_disk/da24s008/lib/python3.10/site-packages/wandb/sdk/lib/sock_client.py", line 154, in send_server_request
    self._send_message(msg)
  File "/mnt/e_disk/da24s008/lib/python3.10/site-packages/wandb/sdk/lib/sock_client.py", line 151, in _send_message
    self._sendall_with_error_handle(header + data)
  File "/mnt/e_disk/da24s008/lib/python3.10/site-packages/wandb/sdk/lib/sock_client.py", line 130, in _sendall_with_error_handle
    sent = self._sock.send(data)
BrokenPipeError: [Errno 32] Broken pipe
